Workbook

Sheet Ventiladores
A1: Voltagens | B1: Modelos | C1: Código | D1: Ventiladores | E1: Descrição | F1: Quantidades
A2: 127 V 50cm | B2: 1 | C2: 100001 | D2: VENTILADOR DOMINA OSCILANTE MESA 50 CM 127 V PRETO | E2: MESA 50 CM 127 V PRETO | F2: 0
A3: 127 V 50cm | B3: 1 | C3: 100002 | D3: VENTILADOR DOMINA OSCILANTE MESA 50 CM 127 V BRANCO | E3: MESA 50 CM 127 V BRANCO | F3: 0
A4: 127 V 50cm | B4: 1 | C4: 100003 | D4: VENTILADOR DOMINA OSCILANTE MESA 50 CM 127 V AÇAI | E4: MESA 50 CM 127 V AÇAI | F4: 0
A5: 127 V 50cm | B5: 1 | C5: 100004 | D5: VENTILADOR DOMINA OSCILANTE MESA 50 CM 127 V VERMELHO | E5: MESA 50 CM 127 V VERMELHO | F5: 0
A6: 127 V 50cm | B6: 1 | C6: 100005 | D6: VENTILADOR DOMINA OSCILANTE MESA 50 CM 127 V CAPPUCCINO | E6: MESA 50 CM 127 V CAPPUCCINO | F6: 0
A7: 127 V 50cm | B7: 1 | C7: 100006 | D7: VENTILADOR DOMINA OSCILANTE MESA 50 CM 127 V OURO | E7: MESA 50 CM 127 V OURO | F7: 0
A8: 127 V 50cm | B8: 1 | C8: 100007 | D8: VENTILADOR DOMINA OSCILANTE MESA 50 CM 127 V BRONZE | E8: MESA 50 CM 127 V BRONZE | F8: 0
A9: 127 V 50cm | B9: 1 | C9: 100008 | D9: VENTILADOR DOMINA OSCILANTE MESA 50 CM 127 V PRATA | E9: MESA 50 CM 127 V PRATA | F9: 0
A10: 127 V 50cm | B10: 1 | C10: 100009 | D10: VENTILADOR DOMINA OSCILANTE MESA 50 CM 127 V TITANIUM | E10: MESA 50 CM 127 V TITANIUM | F10: 0
A11: 127 V 50cm | B11: 1 | C11: 100010 | E11: MESA 50 CM 127 V DARK | F11: 0
A12: 128 V 50cm | B12: 1 | C12: 100011 | E12: MESA 50 CM 127 V ROSA | F12: 0
A13: 127 V 50cm | B13: 2 | C13: 101001 | D13: VENTILADOR DOMINA OSCILANTE PAREDE 50 CM 127 V PRETO | E13: PAREDE 50 CM 127 V PRETO | F13: 0
A14: 127 V 50cm | B14: 2 | C14: 101002 | D14: VENTILADOR DOMINA OSCILANTE PAREDE 50 CM 127 V BRANCO | E14: PAREDE 50 CM 127 V BRANCO | F14: 0
A15: 127 V 50cm | B15: 2 | C15: 101003 | D15: VENTILADOR DOMINA OSCILANTE PAREDE 50 CM 127 V AÇAI | E15: PAREDE 50 CM 127 V AÇAI | F15: 0
A16: 127 V 50cm | B16: 2 | C16: 101007 | D16: VENTILADOR DOMINA OSCILANTE PAREDE 50 CM 127 V BRONZE | E16: PAREDE 50 CM 127 V BRONZE | F16: 0
A17: 127 V 50cm | B17: 2 | C17: 101008 | D17: VENTILADOR DOMINA OSCILANTE PAREDE 50 CM 127 V PRATA | E17: PAREDE 50 CM 127 V PRATA | F17: 0
A18: 127 V 50cm | B18: 2 | C18: 101009 | D18: VENTILADOR DOMINA OSCILANTE PAREDE 50 CM 127 V TITANIUM | E18: PAREDE 50 CM 127 V TITANIUM | F18: 0
A19: 127 V 50cm | B19: 2 | C19: 101010 | E19: PAREDE 50 CM 127 V DARK | F19: 0
A20: 127 V 60cm | B20: 2 | C20: 102001 | D20: VENTILADOR DOMINA ECO OSCILANTE PAREDE 60 CM 127 V PRETO | E20: PAREDE 60 CM 127 V PRETO | F20: 0
A21: 127 V 60cm | B21: 2 | C21: 102002 | D21: VENTILADOR DOMINA ECO OSCILANTE PAREDE 60 CM 127 V BRANCO | E21: PAREDE 60 CM 127 V BRANCO | F21: 0
A22: 127 V 60cm | B22: 2 | C22: 102003 | D22: VENTILADOR DOMINA ECO OSCILANTE PAREDE 60 CM 127 V AÇAI | E22: PAREDE 60 CM 127 V AÇAI | F22: 0
A23: 127 V 60cm | B23: 2 | C23: 102007 | D23: VENTILADOR DOMINA ECO OSCILANTE PAREDE 60 CM 127 V BRONZE | E23: PAREDE 60 CM 127 V BRONZE | F23: 0
A24: 127 V 60cm | B24: 2 | C24: 102008 | D24: VENTILADOR DOMINA ECO OSCILANTE PAREDE 60 CM 127 V PRATA | E24: PAREDE 60 CM 127 V PRATA | F24: 0
A25: 127 V 60cm | B25: 2 | C25: 102009 | D25: VENTILADOR DOMINA ECO OSCILANTE PAREDE 60 CM 127 V TITANIUM | E25: PAREDE 60 CM 127 V TITANIUM | F25: 0
A26: 127 V 60cm | B26: 2 | C26: 102010 | E26: PAREDE 60 CM 127 V DARK | F26: 0
A27: 127 V 50cm | B27: 3 | C27: 103001 | D27: VENTILADOR DOMINA OSCILANTE COLUNA 50 CM 127 V PRETO | E27: COLUNA 50 CM 127 V PRETO | F27: 0
A28: 127 V 50cm | B28: 3 | C28: 103002 | D28: VENTILADOR DOMINA OSCILANTE COLUNA 50 CM 127 V BRANCO | E28: COLUNA 50 CM 127 V BRANCO | F28: 0
A29: 127 V 50cm | B29: 3 | C29: 103003 | D29: VENTILADOR DOMINA OSCILANTE COLUNA 50 CM 127 V AÇAI | E29: COLUNA 50 CM 127 V AÇAI | F29: 0
A30: 127 V 50cm | B30: 3 | C30: 103004 | D30: VENTILADOR DOMINA OSCILANTE COLUNA 50 CM 127 V VERMELHO | E30: COLUNA 50 CM 127 V VERMELHO | F30: 0
A31: 127 V 50cm | B31: 3 | C31: 103005 | D31: VENTILADOR DOMINA OSCILANTE COLUNA 50 CM 127 V CAPPUCCINO | E31: COLUNA 50 CM 127 V CAPPUCCINO | F31: 0
A32: 127 V 50cm | B32: 3 | C32: 103006 | D32: VENTILADOR DOMINA OSCILANTE COLUNA 50 CM 127 V OURO | E32: COLUNA 50 CM 127 V OURO | F32: 0
A33: 127 V 50cm | B33: 3 | C33: 103007 | D33: VENTILADOR DOMINA OSCILANTE COLUNA 50 CM 127 V BRONZE | E33: COLUNA 50 CM 127 V BRONZE | F33: 0
A34: 127 V 50cm | B34: 3 | C34: 103008 | D34: VENTILADOR DOMINA OSCILANTE COLUNA 50 CM 127 V PRATA | E34: COLUNA 50 CM 127 V PRATA | F34: 0
A35: 127 V 50cm | B35: 3 | C35: 103009 | D35: VENTILADOR DOMINA OSCILANTE COLUNA 50 CM 127 V TITANIUM | E35: COLUNA 50 CM 127 V TITANIUM | F35: 0
A36: 127 V 50cm | B36: 3 | C36: 103010 | E36: COLUNA 50 CM 127 V DARK | F36: 0
A37: 128 V 50cm | B37: 3 | C37: 103011 | E37: COLUNA 50 CM 127 V ROSA | F37: 0
A38: 127 V 60cm | B38: 3 | C38: 104001 | D38: VENTILADOR DOMINA ECO OSCILANTE COLUNA 60 CM 127 V PRETO | E38: COLUNA 60 CM 127 V PRETO | F38: 0
A39: 127 V 60cm | B39: 3 | C39: 104002 | D39: VENTILADOR DOMINA ECO OSCILANTE COLUNA 60 CM 127 V BRANCO | E39: COLUNA 60 CM 127 V BRANCO | F39: 0
A40: 127 V 60cm | B40: 3 | C40: 104003 | D40: VENTILADOR DOMINA ECO OSCILANTE COLUNA 60 CM 127 V AÇAI | E40: COLUNA 60 CM 127 V AÇAI | F40: 0
...

Sheet Semi Acabados
E1: Carga -
A2: Código | B2: MOTOR | C2: QNT | E2: Código | F2: Suportes (ECO) | G2: Quant | I2: Código | J2: Motores (ECO) | K2: Quant | M2: Código | N2: Suportes 127 V - 50 cm (ECO) | O2: Quant
A3: 001.002.001.024 | B3: MOTOR PAREDE PRETO BIVOLT 11,5 UNIVERSAL | C3: =Ventiladores!F157+Ventiladores!F162+Ventiladores!F163 -> 0 | E3: 003.003.00082 | F3: Suporte Mesa Preto | G3: =SUM(Ventiladores!F2,Ventiladores!F10,Ventiladores!F11,Ventiladores!F65,Ventiladores!F74,Ventiladores!F82,Ventiladores!F83,Ventiladores!F137,Ventiladores!F146,Ventiladores!F154,Ventiladores!F155) -> 0 | I3: 001.004.021 | J3: 127 V - 50cm AL | K3: =SUM(Ventiladores!F2:F19,Ventiladores!F27:F37) -> 0 | M3: 1001105001 | N3: PRACTICE 50 CM 127 V PRETO | O3: =SUM(Ventiladores!F47) -> 0
A4: 001.002.001.029 | B4: MOTOR PAREDE BRANCO BIVOLT 11,5 | C4: =Ventiladores!F158 -> 0 | E4: 003.003.00083 | F4: Suporte Mesa Branco | G4: =SUM(Ventiladores!F3,Ventiladores!F75,Ventiladores!F147) -> 0 | I4: 001.004.022 | J4: 220 V - 50 cm AL | K4: =SUM(Ventiladores!F74:F91,Ventiladores!F99:F109) -> 0 | M4: 1001105002 | N4: PRACTICE 50 CM 127 V BRANCO | O4: =SUM(Ventiladores!F48) -> 0
A5: 001.002.001.036 | B5: MOTOR PAREDE AÇAÍ BIVOLT 11,5 | C5: =Ventiladores!F159 -> 0 | E5: 003.003.00084 | F5: Suporte Mesa Açaí | G5: =SUM(Ventiladores!F4,Ventiladores!F76,Ventiladores!F148,Ventiladores!F61,Ventiladores!F133) -> 0 | I5: 001.004.009 | J5: 127 V - 60 cm AL | K5: =SUM(Ventiladores!F20:F26,Ventiladores!F38:F46,Ventiladores!F54:F60) -> 0 | M5: 1001105003 | N5: PRACTICE 50 CM 127 V ACAI | O5: =SUM(Ventiladores!F49) -> 0
A6: 001.002.001.041 | B6: MOTOR PAREDE PRATA BIVOLT 11,5 | C6: =Ventiladores!F161 -> 0 | E6: 003.003.00085 | F6: Suporte Mesa Vermelho | G6: =SUM(Ventiladores!F5,Ventiladores!F62,Ventiladores!F77,Ventiladores!F134,Ventiladores!F149) -> 0 | I6: 001.004.022 | J6: 220 V - 60 cm AL | K6: =SUM(Ventiladores!F92:F98,Ventiladores!F110:F118,Ventiladores!F126:F132) -> 0 | M6: 1001105007 | N6: PRACTICE 50 CM 127 V BRONZE | O6: =SUM(Ventiladores!F50) -> 0
A7: 001.002.001.043 | B7: MOTOR COLUNA/MESA AÇAÍ BIVOLT 11,5 | C7: =Ventiladores!F173+Ventiladores!F148 -> 0 | E7: 003.003.00086 | F7: Suporte Mesa Cappuccino | G7: =SUM(Ventiladores!F6,Ventiladores!F78,Ventiladores!F150) -> 0 | I7: 001.004.023 | J7: Bivolt - 50 cm (Mesa/Coluna) | K7: =SUM(Ventiladores!F146:F163,Ventiladores!F171:F181) -> 0 | M7: 1001105008 | N7: PRACTICE 50 CM 127 V PRATA | O7: =SUM(Ventiladores!F51) -> 0
A8: 001.002.001.049 | B8: MOTOR COLUNA/MESA BRANCO BIVOLT 11,5 | C8: =Ventiladores!F172+Ventiladores!F147 -> 0 | E8: 003.003.00087 | F8: Suporte Mesa Dourado | G8: =SUM(Ventiladores!F7,Ventiladores!F79,Ventiladores!F151) -> 0 | I8: 001.004.023 | J8: Bivolt - 50 cm (Parede) | K8: =SUM(Ventiladores!F157:F163) -> 0 | M8: 1001105009 | N8: PRACTICE 50 CM 127 V TITANIUM | O8: =SUM(Ventiladores!F52) -> 0
A9: 001.002.001.051 | B9: MOTOR COLUNA/MESA PRATA BIVOLT 11,5 | C9: =Ventiladores!F178+Ventiladores!F153 -> 0 | E9: 003.003.00088 | F9: Suporte Mesa Bronze | G9: =SUM(Ventiladores!F8,Ventiladores!F63,Ventiladores!F80,Ventiladores!F135,Ventiladores!F152) -> 0 | I9: 001.004.023 | J9: Bivolt - 60 cm (Mesa/Coluna) | K9: =SUM(Ventiladores!F182:F190) -> 0 | M9: 1001105010 | N9: PRACTICE 50 CM 127 V DARK | O9: =SUM(Ventiladores!F53) -> 0
A10: 001.002.001.053 | B10: MOTOR COLUNA/MESA PRETO BIVOLT 11,5 UNIVERSAL | C10: =Ventiladores!F171+Ventiladores!F146+Ventiladores!F179+Ventiladores!F154+Ventiladores!F180+Ventiladores!F155 -> 0 | E10: 003.003.00089 | F10: Suporte Mesa Prata | G10: =SUM(Ventiladores!F9,Ventiladores!F81,Ventiladores!F153,Ventiladores!F64,Ventiladores!F136) -> 0 | I10: 001.004.023 | J10: Bivolt - 60 cm (Parede) | K10: =SUM(Ventiladores!F164:F170) -> 0 | M10: Total | O10: =SUM(O3,O4,O5,O6,O7,O8,O9) -> 0
A11: 001.002.001.061 | B11: MOTOR COLUNA/MESA VERMELHO BIVOLT 11,5 | C11: =Ventiladores!F174+Ventiladores!F149 -> 0 | E11: 003.003.00154 | F11: Suporte Mesa Rosa | G11: =SUM(Ventiladores!F12,Ventiladores!F84,Ventiladores!F156) -> 0 | I11: 001.004.031 | J11: 127 V - 4.3 cm AL | K11: =SUM(Ventiladores!F61:F66) -> 0
A12: 001.002.001.063 | B12: MOTOR COLUNA/MESA OURO BIVOLT 11,5 | C12: =Ventiladores!F176+Ventiladores!F151 -> 0 | E12: 003.003.00090 | F12: Suporte Parede Preto | G12: =SUM(Ventiladores!F13,Ventiladores!F18,Ventiladores!F19,Ventiladores!F20,Ventiladores!F25,Ventiladores!F26,Ventiladores!F66,Ventiladores!F85,Ventiladores!F90,Ventiladores!F91,Ventiladores!F92,Ventiladores!F97,Ventiladores!F98,Ventiladores!F157,Ventiladores!F162,Ventiladores!F163,Ventiladores!F164,Ventiladores!F169,Ventiladores!F170) -> 0 | I12: 001.004.032 | J12: 220 V - 4.3 cm AL | K12: =SUM(Ventiladores!F133:F138) -> 0 | M12: Código | N12: Suportes 127 V - 60 cm (ECO) | O12: Quant
A13: 001.002.001.095 | B13: MOTOR COLUNA/MESA BRONZE BIVOLT 11,5 | C13: =Ventiladores!F177+Ventiladores!F152 -> 0 | E13: 003.003.00091 | F13: Suporte Parede Branco | G13: =SUM(Ventiladores!F14,Ventiladores!F21,Ventiladores!F86,Ventiladores!F93,Ventiladores!F158,Ventiladores!F165) -> 0 | I13: Total | K13: =SUM(K3,K4,K9,K10,K11,K12) -> 0 | M13: 1001106001 | N13: PRACTICE 60 CM 127 V PRETO | O13: =SUM(Ventiladores!F54) -> 0
A14: 001.002.001.098 | B14: MOTOR COLUNA/MESA CAPPUCCINO BIVOLT 11,5 | C14: =Ventiladores!F175+Ventiladores!F150 -> 0 | E14: 003.003.00092 | F14: Suporte Parede Açaí | G14: =SUM(Ventiladores!F15,Ventiladores!F22,Ventiladores!F87,Ventiladores!F94,Ventiladores!F159,Ventiladores!F166) -> 0 | M14: 1001106002 | N14: PRACTICE 60 CM 127 V BRANCO | O14: =SUM(Ventiladores!F55) -> 0
A15: 001.002.001.100 | B15: MOTOR PAREDE BRONZE BIVOLT 11,5 | C15: =Ventiladores!F160 -> 0 | E15: 003.003.00094 | F15: Suporte Parede Bronze | G15: =SUM(Ventiladores!F16,Ventiladores!F23,Ventiladores!F88,Ventiladores!F95,Ventiladores!F160,Ventiladores!F167) -> 0 | I15: Código | J15: Suportes - Practice (ECO) | K15: CX | M15: 1001106003 | N15: PRACTICE 60 CM 127 V ACAI | O15: =SUM(Ventiladores!F56) -> 0
A16: 001.002.002.027 | B16: MOTOR PAREDE BRANCO 220 V 11,5 | C16: =Ventiladores!F86 -> 0 | E16: 003.003.00095 | F16: Suporte Parede Prata | G16: =SUM(Ventiladores!F17,Ventiladores!F24,Ventiladores!F89,Ventiladores!F96,Ventiladores!F161,Ventiladores!F168) -> 0 | I16: 003.001.00202 | J16: Suporte Practice Preto | K16: =SUM(O3,O8,O9,O13,O18,O19,O23,O28,O29,O33,O38,O39) -> 0 | M16: 1001106007 | N16: PRACTICE 60 CM 127 V BRONZE | O16: =SUM(Ventiladores!F57) -> 0
A17: 001.002.002.028 | B17: MOTOR PAREDE PRETO 220 V 11,5 UNIVERSAL | C17: =Ventiladores!F85+Ventiladores!F90+Ventiladores!F91 -> 0 | E17: Total | G17: =SUM(G3,G4,G5,G6,G7,G8,G9,G10,G12,G13,G14,G15,G16) -> 0 | I17: 003.001.00203 | J17: Suporte Practice Branco | K17: =SUM(O4,O14,O24,O34) -> 0 | M17: 1001106008 | N17: PRACTICE 60 CM 127 V PRATA | O17: =SUM(Ventiladores!F58) -> 0
A18: 001.002.002.037 | B18: MOTOR PAREDE PRATA 220 V 11,5 | C18: =Ventiladores!F89 -> 0 | I18: 003.001.00204 | J18: Suporte Practice Açaí | K18: =SUM(O5,O15,O25,O35) -> 0 | M18: 1001106009 | N18: PRACTICE 60 CM 127 V TITANIUM | O18: =SUM(Ventiladores!F59) -> 0
A19: 001.002.002.041 | B19: MOTOR PAREDE AÇAÍ 220 V 11,5 | C19: =Ventiladores!F87 -> 0 | E19: Código | F19: Controle de Parede (ECO) | G19: Quant | I19: 003.001.00205 | J19: Suporte Practice Bronze | K19: =SUM(O6,O16,O26,O36) -> 0 | M19: 1001106010 | N19: PRACTICE 60 CM 127 V DARK | O19: =SUM(Ventiladores!F60) -> 0
A20: 001.002.002.043 | B20: MOTOR COLUNA/MESA AÇAÍ 220 V 11,5 | C20: =Ventiladores!F76+Ventiladores!F101 -> 0 | E20: 003.003.00028 | F20: Controle de Parede 127 V - 50 cm | G20: =SUM(Ventiladores!F13:F19,Ventiladores!F66) -> 0 | I20: 003.001.00206 | J20: Suporte Practice Prata | K20: =SUM(O7,O17,O27,O37) -> 0 | M20: Total | O20: =SUM(O13,O14,O15,O16,O17,O18,O19) -> 0
A21: 001.002.002.049 | B21: MOTOR COLUNA/MESA BRANCO 220 V 11,5 | C21: =Ventiladores!F75+Ventiladores!F100 -> 0 | E21: 003.003.00030 | F21: Controle de Parede 127 V - 60 cm | G21: =SUM(Ventiladores!F20:F26) -> 0 | I21: Total | K21: =SUM(K16,K17,K18,K19,K20) -> 0
A22: 001.002.002.051 | B22: MOTOR COLUNA/MESA PRATA 220 V 11,5 | C22: =Ventiladores!F81+Ventiladores!F106 -> 0 | E22: 003.003.00029 | F22: Controle de Parede 220 V - 50 cm | G22: =SUM(Ventiladores!F85:F91,Ventiladores!F138) -> 0 | M22: Código | N22: Suportes 220 V - 50 cm (ECO) | O22: Quant
A23: 001.002.002.053 | B23: MOTOR COLUNA/MESA PRETO 220 V 11,5 UNIVERSAL | C23: =Ventiladores!F74+Ventiladores!F99+Ventiladores!F82+Ventiladores!F107+Ventiladores!F83+Ventiladores!F108 -> 0 | E23: 003.003.00031 | F23: Controle de Parede 220 V - 60 cm | G23: =SUM(Ventiladores!F92,Ventiladores!F93,Ventiladores!F94,Ventiladores!F95,Ventiladores!F96,Ventiladores!F97,Ventiladores!F98) -> 0 | I23: Código | J23: Manípulo - Practice (ECO) | K23: Quant | M23: 1001205001 | N23: PRACTICE 50 CM 220 V PRETO | O23: =SUM(Ventiladores!F119) -> 0
A24: 001.002.002.061 | B24: MOTOR COLUNA/MESA VERMELHO 220 V 11,5 | C24: =Ventiladores!F77+Ventiladores!F102 -> 0 | E24: 003.003.00032 | F24: Controle de Parede Bivolt - 50 cm | G24: =SUM(Ventiladores!F157:F163) -> 0 | I24: 003.001.00116 | J24: Manípulo Practice Preto | K24: =SUM(O3,O13,O23,O33) -> 0 | M24: 1001205002 | N24: PRACTICE 50 CM 220 V BRANCO | O24: =SUM(Ventiladores!F120) -> 0
A25: 001.002.002.063 | B25: MOTOR COLUNA/MESA OURO 220 V 11,5 | C25: =Ventiladores!F79+Ventiladores!F104 -> 0 | E25: 003.003.00033 | F25: Controle de Parede Bivolt - 60 cm | G25: =SUM(Ventiladores!F164:F170) -> 0 | I25: 003.001.00128 | J25: Manípulo Practice Prata | K25: =SUM(O4,O5,O7,O8,O14,O15,O17,O18,O24,O25,O27,O28,O34,O35,O37,O38) -> 0 | M25: 1001205003 | N25: PRACTICE 50 CM 220 V ACAI | O25: =SUM(Ventiladores!F121) -> 0
A26: 001.002.002.071 | B26: MOTOR PRACTICE PRETO 220 V 11,5 UNIVERSAL | C26: =Ventiladores!F124+Ventiladores!F125+Ventiladores!F119 -> 0 | E26: Total | G26: =SUM(G20,G21,G22,G23,G24,G25) -> 0 | I26: 003.001.00172 | J26: Manípulo Practice Bronze | K26: =SUM(O6,O16,O26,O36) -> 0 | M26: 1001205007 | N26: PRACTICE 50 CM 220 V BRONZE | O26: =SUM(Ventiladores!F122) -> 0
A27: 001.002.002.072 | B27: MOTOR PRACTICE BRANCO 220 V 11,5 | C27: =Ventiladores!F120 -> 0 | I27: 003.001.00129 | J27: Manípulo Practice Dourado | K27: =SUM(O9,O19,O29,O39) -> 0 | M27: 1001205008 | N27: PRACTICE 50 CM 220 V PRATA | O27: =SUM(Ventiladores!F123) -> 0
A28: 001.002.002.079 | B28: MOTOR PRACTICE AÇAÍ 220 V 11,5 | C28: =Ventiladores!F121 -> 0 | E28: Código | F28: Kits (ECO) | G28: Quant | I28: Total | K28: =SUM(K24,K25,K26,K27) -> 0 | M28: 1001205009 | N28: PRACTICE 50 CM 220 V TITANIUM | O28: =SUM(Ventiladores!F124) -> 0
A29: 001.002.002.080 | B29: MOTOR PRACTICE PRATA 220 V 11,5 | C29: =Ventiladores!F123 -> 0 | E29: 003.003.00017 | F29: Kit Componentes | G29: =SUM(Ventiladores!F27:F46,Ventiladores!F99:F118,Ventiladores!F171:F190) -> 0 | M29: 1001205010 | N29: PRACTICE 50 CM 220 V DARK | O29: =SUM(Ventiladores!F125) -> 0
A30: 001.002.002.094 | B30: MOTOR COLUNA/MESA CAPPUCCINO 220 V 11,5 | C30: =Ventiladores!F78+Ventiladores!F103 -> 0 | E30: 003.003.00020 | F30: Kit Fixação | G30: =SUM(Ventiladores!F13:F26,Ventiladores!F47:F53,Ventiladores!F53,Ventiladores!F54:F60,Ventiladores!F66,Ventiladores!F85:F98,Ventiladores!F119:F132,Ventiladores!F138,Ventiladores!F157:F170) -> 0 | I30: Código | J30: Dimmer - Practice (ECO) | K30: Quant | M30: Total | O30: =SUM(O23,O24,O25,O26,O27,O28,O29) -> 0
A31: 001.002.002.098 | B31: MOTOR COLUNA/MESA BRONZE 220 V 11,5 | C31: =Ventiladores!F80+Ventiladores!F105 -> 0 | E31: Total | G31: =SUM(G29,G30) -> 0 | I31: 002.001.00022 | J31: Dimmer Practice 127 V - 50 cm | K31: =SUM(O10) -> 0
A32: 001.002.002.100 | B32: MOTOR PAREDE BRONZE 220 V 11,5 | C32: =Ventiladores!F88 -> 0 | I32: 002.001.00065 | J32: Dimmer Practice 127 V - 60 cm | K32: =SUM(O20) -> 0 | M32: Código | N32: Suportes 220 V - 60 cm (ECO) | O32: Quant
A33: 001.002.002.102 | B33: MOTOR PRACTICE BRONZE 220 V 11,5 | C33: =Ventiladores!F122 -> 0 | E33: Código | F33: Caixa de Engrenagem (ECO) | G33: Quant | I33: 002.001.00025 | J33: Dimmer Practice 220 V - 50 cm | K33: =SUM(O30) -> 0 | M33: 1001206001 | N33: PRACTICE 60 CM 220 V PRETO | O33: =SUM(Ventiladores!F126) -> 0
A34: 001.002.003.017 | B34: MOTOR PAREDE PRETO 127 V 11,5 UNIVERSAL | C34: =Ventiladores!F19 -> 0 | E34: 003.003.00081 | F34: Caixa de Engrenagem 50/60 cm | G34: =SUM(Ventiladores!F2:F60,Ventiladores!F74:F132,Ventiladores!F146:F190) -> 0 | I34: 002.001.00066 | J34: Dimmer Practice 220 V - 60 cm | K34: =SUM(O40) -> 0 | M34: 1001206002 | N34: PRACTICE 60 CM 220 V BRANCO | O34: =SUM(Ventiladores!F127) -> 0
A35: 001.002.003.028 | B35: MOTOR PAREDE BRANCO 127 V 11,5 | C35: =Ventiladores!F14 -> 0 | E35: 003.003.00155 | F35: Caixa de Engrenagem 4.3 cm | G35: =SUM(Ventiladores!F61:F66,Ventiladores!F133:F138) -> 0 | I35: Total | K35: =SUM(K31,K32,K33,K34) -> 0 | M35: 1001206003 | N35: PRACTICE 60 CM 220 V ACAI | O35: =SUM(Ventiladores!F128) -> 0
A36: 001.002.003.036 | B36: MOTOR PAREDE PRATA 127 V 11,5 | C36: =Ventiladores!F17 -> 0 | E36: Total | G36: =SUM(G34/300) -> 0 | M36: 1001206007 | N36: PRACTICE 60 CM 220 V BRONZE | O36: =SUM(Ventiladores!F129) -> 0
A37: 001.002.003.041 | B37: MOTOR PAREDE AÇAÍ 127 V 11,5 | C37: =Ventiladores!F15 -> 0 | I37: Código | J37: Abraçadeira - Ventilador (ECO) | K37: Quant | M37: 1001206008 | N37: PRACTICE 60 CM 220 V PRATA | O37: =SUM(Ventiladores!F130) -> 0
A38: 001.002.003.043 | B38: MOTOR COLUNA/MESA ACAI 127 V 11,5 | C38: =Ventiladores!F4+Ventiladores!F29 -> 0 | E38: Código | F38: Dimmer - Ventilador (ECO) | G38: Mont | I38: 002.004.00010 | J38: Abraçadeira k8 | K38: =SUM(Ventiladores!F2:F190)*2 -> 0 | M38: 1001206009 | N38: PRACTICE 60 CM 220 V TITANIUM | O38: =SUM(Ventiladores!F131) -> 0
A39: 001.002.003.049 | B39: MOTOR COLUNA/MESA BRANCO 127 V 11,5 | C39: =Ventiladores!F3+Ventiladores!F28 -> 0 | E39: 002.001.00007 | F39: Dimmer Bivolt - (50 cm) | G39: =SUM(Ventiladores!F146:F155,Ventiladores!F171:F180) -> 0 | I39: 002.004.00011 | J39: Abraçadeira k12 | K39: =SUM(Ventiladores!F2:F190) -> 0 | M39: 1001206010 | N39: PRACTICE 60 CM 220 V DARK | O39: =SUM(Ventiladores!F132) -> 0
A40: 001.002.003.051 | B40: MOTOR COLUNA/MESA PRATA 127 V 11,5 | C40: =Ventiladores!F9+Ventiladores!F34 -> 0 | E40: 002.001.00084 | F40: Dimmer Bivolt - (60 cm) | G40: =SUM(Ventiladores!F182:F190) -> 0 | I40: Total | K40: =SUM(K38,K39) -> 0 | M40: Total | O40: =SUM(O33,O34,O35,O36,O37,O38,O39) -> 0
...

Sheet Peças Plásticas
B1: OP | D1: Vent. | E1: QTD | F1: OP motor

Sheet Planejamento
B1: Carga -
A2: OPS | B2: 127 V 43 cm | C2: Quant. | D2: Status | E2: Seque. | G2: OPS | H2: 220 V 50 cm | I2: Quant. | J2: Status | K2: Seque.
D3: NI | J3: NI
D4: NI | J4: NI
D5: NI | J5: NI
D6: NI | J6: NI
D7: NI | J7: NI
D8: NI | J8: NI
D9: NI | J9: NI
D10: NI | J10: NI
D11: NI | J11: NI
D12: NI | J12: NI
D13: NI | J13: NI
D14: NI | J14: NI
... D17: NI | J17: NI
A18: OPS | B18: 220 V 43 cm | C18: Quant. | D18: Status | E18: Seque. | J18: NI
D19: NI | J19: NI
D20: NI | J20: NI
D21: NI | J21: NI
D22: NI | J22: NI
D23: NI | J23: NI
D24: NI | J24: NI
D25: NI | J25: NI
D26: NI | J26: NI
D27: NI | G27: OPS | H27: 127 V 60 cm | I27: Quant. | J27: Status | K27: Seque.
D28: NI | J28: NI
D29: NI | J29: NI
D30: NI | J30: NI
A31: OPS | B31: BIVOLT V 50 cm | C31: Quant. | D31: Status | E31: Seque. | J31: NI
D32: NI | J32: NI
D33: NI | J33: NI
D34: NI | J34: NI
D35: NI | J35: NI
D36: NI | J36: NI
D37: NI | J37: NI
D38: NI | J38: NI
D39: NI | J39: NI
D40: NI | G40: OPS | H40: 220 V 60 cm | I40: Quant. | J40: Status | K40: Seque.
D41: NI | J41: NI
D42: NI | J42: NI
...

Sheet Postos de trabalho 
A1: Carga - | H1: PRACTICE | O1: SUPORTE PAREDE
C2: Daisy | H2: DANIEL E IGOR | P2: NATYLIANE
C3: (MOTORES , PINO E KNOB) | H3: RABICHO COM PLUG / RABICHO MACHO | P3: DISCO TRAVA
D4: Esteira | J4: Esteira | R4: Esteira
S5: SAYMON
C6: IGOR | K6: FRANCISVALDO | S6: PARAFUSAR
C7: (GRADE 1°) | K7: CRIMPADORA | P7: DÉBORA
H8: DAYSE | P8: BORBOLETA
E10: CRIMPADORA | H10: SECAGEM E ABRAÇADEIRA
S11: FRANCISVALDO
K13: VINICIUS | S13: EMBALAR
K14: MANÍPULO
B16: SILVAN | E16: VINÍCIUS
B17: (Logomarca) | E17: (GRADE 2°) | H17: SAYMON | P17: DAYSE
E18: (Grade 2°)
H19: PARAFUSADEIRA | P19: DISCO TRAVA
H24: DÉBORA
E25: MESA DE FERRAMENTAS | H25: TESTE DE PRACTICE | P25: IGOR
C26: 0 | P26: PARAFUSAR
C27: (TESTE 1°) | F27: DENILSON | K27: NATYLIANE | S27: DANIEL
F28: (Retrabalho) | K28: EMBALAGEM E BORBOLETA | S28: BORBOLETA
E31: NATYLIANE
E32: (teste 2°) | G32: FÉRIAS
E33: (TESTE 2°)
C42: DANIEL | E42: DÉBORA | S42: VINICIUS
C43: (Embalagem) | E43: (Etiqueta) | S43: EMBALAR
E44: Fabio
B45: FRANCISVALDO
B46: (Kit)
E47: SAYMON
E48: (Final)
A49: BASE ESTRELA ECO | H49: SUPORTE MESA | O49: CONTROLES
C52: DÉBORA/FRAN | H52: NATYLIANE | P52: DÉBORA / FRAN
C53: ETIQUETA | H53: ETIQUETA/DISCO TRAVA | P53: DIMMER/ARRUELA E PORCA
D54: Esteira | J54: Esteira | K54: SAYMON | R54: Esteira | S54: SAYMON
K55: PARAFUSAR | S55: PARAFUSAR
P57: DAYSE
C58: DAYSE | H58: DAYSE | P58: ETIQUETA/KNOB
C59: EMBALAR | H59: BORBOLETA | S59: NATYLIANE
E60: JULIO | K60: DANIEL | S60: GRAMPEAR | U60: CAIXA
...
